2024-10-16 17:40:03,673 Minimum price: 10, Maximum price: 350
2024-10-16 17:40:03,702 Preparing sklearn pipeline
2024-10-16 17:40:03,703 Fitting
Traceback (most recent call last):
  File "/home/lhan/miniconda3/envs/mlflow-211c8fb974d6215abb361efdc7b6c4bd9a3e8dfd/lib/python3.10/site-packages/pandas/core/indexes/base.py", line 3790, in get_loc
    return self._engine.get_loc(casted_key)
  File "index.pyx", line 152, in pandas._libs.index.IndexEngine.get_loc
  File "index.pyx", line 181, in pandas._libs.index.IndexEngine.get_loc
  File "pandas/_libs/hashtable_class_helper.pxi", line 7080, in pandas._libs.hashtable.PyObjectHashTable.get_item
  File "pandas/_libs/hashtable_class_helper.pxi", line 7088, in pandas._libs.hashtable.PyObjectHashTable.get_item
KeyError: 'processed_features'
The above exception was the direct cause of the following exception:
Traceback (most recent call last):
  File "/home/lhan/Project-Build-an-ML-Pipeline-Starter/src/train_random_forest/run.py", line 305, in <module>
    go(args)
  File "/home/lhan/Project-Build-an-ML-Pipeline-Starter/src/train_random_forest/run.py", line 79, in go
    sk_pipe.fit(X_train['processed_features'], y_train)
  File "/home/lhan/miniconda3/envs/mlflow-211c8fb974d6215abb361efdc7b6c4bd9a3e8dfd/lib/python3.10/site-packages/pandas/core/frame.py", line 3893, in __getitem__
    indexer = self.columns.get_loc(key)
  File "/home/lhan/miniconda3/envs/mlflow-211c8fb974d6215abb361efdc7b6c4bd9a3e8dfd/lib/python3.10/site-packages/pandas/core/indexes/base.py", line 3797, in get_loc
    raise KeyError(key) from err
KeyError: 'processed_features'